2025-06-19 15:37:05,248 - INFO - Starting ticket data collection scheduler...
2025-06-19 15:37:05,250 - INFO - Scheduler started. Press Ctrl+C to stop.
2025-06-19 16:07:17,050 - INFO - Starting ticket data collection scheduler...
2025-06-19 16:07:17,052 - INFO - Scheduler started. Press Ctrl+C to stop.
2025-06-21 00:26:30,490 - INFO - Starting ticketmaster event collection...
2025-06-21 00:26:34,346 - ERROR - Ticketmaster script failed with return code 1
2025-06-21 00:26:34,346 - ERROR - Error: Traceback (most recent call last):
  File "C:\Users\zarak\OneDrive\Documents\GitHub\ticket_model\.venv\Lib\site-packages\urllib3\connection.py", line 198, in _new_conn
    sock = connection.create_connection(
        (self._dns_host, self.port),
    ...<2 lines>...
        socket_options=self.socket_options,
    )
  File "C:\Users\zarak\OneDrive\Documents\GitHub\ticket_model\.venv\Lib\site-packages\urllib3\util\connection.py", line 85, in create_connection
    raise err
  File "C:\Users\zarak\OneDrive\Documents\GitHub\ticket_model\.venv\Lib\site-packages\urllib3\util\connection.py", line 73, in create_connection
    sock.connect(sa)
    ~~~~~~~~~~~~^^^^
OSError: [WinError 10051] A socket operation was attempted to an unreachable network

The above exception was the direct cause of the following exception:

Traceback (most recent call last):
  File "C:\Users\zarak\OneDrive\Documents\GitHub\ticket_model\.venv\Lib\site-packages\urllib3\connectionpool.py", line 787, in urlopen
    response = self._make_request(
        conn,
    ...<10 lines>...
        **response_kw,
    )
  File "C:\Users\zarak\OneDrive\Documents\GitHub\ticket_model\.venv\Lib\site-packages\urllib3\connectionpool.py", line 488, in _make_request
    raise new_e
  File "C:\Users\zarak\OneDrive\Documents\GitHub\ticket_model\.venv\Lib\site-packages\urllib3\connectionpool.py", line 464, in _make_request
    self._validate_conn(conn)
    ~~~~~~~~~~~~~~~~~~~^^^^^^
  File "C:\Users\zarak\OneDrive\Documents\GitHub\ticket_model\.venv\Lib\site-packages\urllib3\connectionpool.py", line 1093, in _validate_conn
    conn.connect()
    ~~~~~~~~~~~~^^
  File "C:\Users\zarak\OneDrive\Documents\GitHub\ticket_model\.venv\Lib\site-packages\urllib3\connection.py", line 753, in connect
    self.sock = sock = self._new_conn()
                       ~~~~~~~~~~~~~~^^
  File "C:\Users\zarak\OneDrive\Documents\GitHub\ticket_model\.venv\Lib\site-packages\urllib3\connection.py", line 213, in _new_conn
    raise NewConnectionError(
        self, f"Failed to establish a new connection: {e}"
    ) from e
urllib3.exceptions.NewConnectionError: <urllib3.connection.HTTPSConnection object at 0x00000253D033A990>: Failed to establish a new connection: [WinError 10051] A socket operation was attempted to an unreachable network

The above exception was the direct cause of the following exception:

Traceback (most recent call last):
  File "C:\Users\zarak\OneDrive\Documents\GitHub\ticket_model\.venv\Lib\site-packages\requests\adapters.py", line 667, in send
    resp = conn.urlopen(
        method=request.method,
    ...<9 lines>...
        chunked=chunked,
    )
  File "C:\Users\zarak\OneDrive\Documents\GitHub\ticket_model\.venv\Lib\site-packages\urllib3\connectionpool.py", line 841, in urlopen
    retries = retries.increment(
        method, url, error=new_e, _pool=self, _stacktrace=sys.exc_info()[2]
    )
  File "C:\Users\zarak\OneDrive\Documents\GitHub\ticket_model\.venv\Lib\site-packages\urllib3\util\retry.py", line 519, in increment
    raise MaxRetryError(_pool, url, reason) from reason  # type: ignore[arg-type]
    ^^^^^^^^^^^^^^^^^^^^^^^^^^^^^^^^^^^^^^^^^^^^^^^^^^^
urllib3.exceptions.MaxRetryError: HTTPSConnectionPool(host='app.ticketmaster.com', port=443): Max retries exceeded with url: /discovery/v2/events/Z7r9jZ1A7u-Ak.json?apikey=KntBcmnLD8BBG0DpsV1GMMakFSFcoaof&id=Z7r9jZ1A7u-Ak (Caused by NewConnectionError('<urllib3.connection.HTTPSConnection object at 0x00000253D033A990>: Failed to establish a new connection: [WinError 10051] A socket operation was attempted to an unreachable network'))

During handling of the above exception, another exception occurred:

Traceback (most recent call last):
  File "C:\Users\zarak\OneDrive\Documents\GitHub\ticket_model\ticketmaster_eventgetter.py", line 118, in <module>
    detail_resp = requests.get(url_EventDetail)
  File "C:\Users\zarak\OneDrive\Documents\GitHub\ticket_model\.venv\Lib\site-packages\requests\api.py", line 73, in get
    return request("get", url, params=params, **kwargs)
  File "C:\Users\zarak\OneDrive\Documents\GitHub\ticket_model\.venv\Lib\site-packages\requests\api.py", line 59, in request
    return session.request(method=method, url=url, **kwargs)
           ~~~~~~~~~~~~~~~^^^^^^^^^^^^^^^^^^^^^^^^^^^^^^^^^^
  File "C:\Users\zarak\OneDrive\Documents\GitHub\ticket_model\.venv\Lib\site-packages\requests\sessions.py", line 589, in request
    resp = self.send(prep, **send_kwargs)
  File "C:\Users\zarak\OneDrive\Documents\GitHub\ticket_model\.venv\Lib\site-packages\requests\sessions.py", line 703, in send
    r = adapter.send(request, **kwargs)
  File "C:\Users\zarak\OneDrive\Documents\GitHub\ticket_model\.venv\Lib\site-packages\requests\adapters.py", line 700, in send
    raise ConnectionError(e, request=request)
requests.exceptions.ConnectionError: HTTPSConnectionPool(host='app.ticketmaster.com', port=443): Max retries exceeded with url: /discovery/v2/events/Z7r9jZ1A7u-Ak.json?apikey=KntBcmnLD8BBG0DpsV1GMMakFSFcoaof&id=Z7r9jZ1A7u-Ak (Caused by NewConnectionError('<urllib3.connection.HTTPSConnection object at 0x00000253D033A990>: Failed to establish a new connection: [WinError 10051] A socket operation was attempted to an unreachable network'))

